Workbook

Sheet المواد المسجلة
A1: الرقم الجامعي | B1: رمز المادة | C1: اسم المادة | D1: الوحدات | E1: المحاضر | F1: موعد المحاضرة
A2: =[1]Sheet2!A2 -> 4800 | B2: =[1]Sheet2!B2 -> 2804 | C2: =VLOOKUP(B2,الجدول!A:B,2,FALSE) -> English Grammar D | D2: =VLOOKUP(B2,الجدول!A:E,5,FALSE) -> 4 | E2: =VLOOKUP(B2,الجدول!A:D,4,FALSE) -> د. عبدالسلام الرقاص | F2: =VLOOKUP(B2,الجدول!A:D,3,FALSE) -> الإربعاء 01:00
A3: =[1]Sheet2!A3 -> 4808 | B3: =[1]Sheet2!B3 -> 2515 | C3: =VLOOKUP(B3,الجدول!A:B,2,FALSE) -> Psycho. Linguistics | D3: =VLOOKUP(B3,الجدول!A:E,5,FALSE) -> 3 | E3: =VLOOKUP(B3,الجدول!A:D,4,FALSE) -> أ. خديجة العشيبي | F3: =VLOOKUP(B3,الجدول!A:D,3,FALSE) -> السبت 11:00
A4: =[1]Sheet2!A4 -> 4808 | B4: =[1]Sheet2!B4 -> 2815 | C4: =VLOOKUP(B4,الجدول!A:B,2,FALSE) -> CALL | D4: =VLOOKUP(B4,الجدول!A:E,5,FALSE) -> 3 | E4: =VLOOKUP(B4,الجدول!A:D,4,FALSE) -> أ. فرج الجارح | F4: =VLOOKUP(B4,الجدول!A:D,3,FALSE) -> الإربعاء 09:00
A5: =[1]Sheet2!A5 -> 4808 | B5: =[1]Sheet2!B5 -> 2603 | C5: =VLOOKUP(B5,الجدول!A:B,2,FALSE) -> Introduction to ESP | D5: =VLOOKUP(B5,الجدول!A:E,5,FALSE) -> 3 | E5: =VLOOKUP(B5,الجدول!A:D,4,FALSE) -> أ. خديجة العشيبي | F5: =VLOOKUP(B5,الجدول!A:D,3,FALSE) -> السبت 01:00
A6: =[1]Sheet2!A6 -> 4808 | B6: =[1]Sheet2!B6 -> 2614 | C6: =VLOOKUP(B6,الجدول!A:B,2,FALSE) -> Lexicography | D6: =VLOOKUP(B6,الجدول!A:E,5,FALSE) -> 3 | E6: =VLOOKUP(B6,الجدول!A:D,4,FALSE) -> أ. فرج مالك | F6: =VLOOKUP(B6,الجدول!A:D,3,FALSE) -> السبت 09:00
A7: =[1]Sheet2!A7 -> 4808 | B7: =[1]Sheet2!B7 -> 2704 | C7: =VLOOKUP(B7,الجدول!A:B,2,FALSE) -> Semantics | D7: =VLOOKUP(B7,الجدول!A:E,5,FALSE) -> 3 | E7: =VLOOKUP(B7,الجدول!A:D,4,FALSE) -> أ. الشريف الملاح | F7: =VLOOKUP(B7,الجدول!A:D,3,FALSE) -> الأحد 11:00
A8: =[1]Sheet2!A8 -> 4811 | B8: =[1]Sheet2!B8 -> 2812 | C8: =VLOOKUP(B8,الجدول!A:B,2,FALSE) -> Research Project | D8: =VLOOKUP(B8,الجدول!A:E,5,FALSE) -> 4 | E8: =VLOOKUP(B8,الجدول!A:D,4,FALSE) -> 0 | F8: =VLOOKUP(B8,الجدول!A:D,3,FALSE)
A9: =[1]Sheet2!A9 -> 4811 | B9: =[1]Sheet2!B9 -> 2813 | C9: =VLOOKUP(B9,الجدول!A:B,2,FALSE) -> Language Testing | D9: =VLOOKUP(B9,الجدول!A:E,5,FALSE) -> 4 | E9: =VLOOKUP(B9,الجدول!A:D,4,FALSE) -> أ. فرج الجارح | F9: =VLOOKUP(B9,الجدول!A:D,3,FALSE) -> الإربعاء 11:00
A10: =[1]Sheet2!A10 -> 4811 | B10: =[1]Sheet2!B10 -> 2804 | C10: =VLOOKUP(B10,الجدول!A:B,2,FALSE) -> English Grammar D | D10: =VLOOKUP(B10,الجدول!A:E,5,FALSE) -> 4 | E10: =VLOOKUP(B10,الجدول!A:D,4,FALSE) -> د. عبدالسلام الرقاص | F10: =VLOOKUP(B10,الجدول!A:D,3,FALSE) -> الإربعاء 01:00
A11: =[1]Sheet2!A11 -> 4811 | B11: =[1]Sheet2!B11 -> 2815 | C11: =VLOOKUP(B11,الجدول!A:B,2,FALSE) -> CALL | D11: =VLOOKUP(B11,الجدول!A:E,5,FALSE) -> 3 | E11: =VLOOKUP(B11,الجدول!A:D,4,FALSE) -> أ. فرج الجارح | F11: =VLOOKUP(B11,الجدول!A:D,3,FALSE) -> الإربعاء 09:00
A12: =[1]Sheet2!A12 -> 5163 | B12: =[1]Sheet2!B12 -> 2512 | C12: =VLOOKUP(B12,الجدول!A:B,2,FALSE) -> Phonetics and Phonology | D12: =VLOOKUP(B12,الجدول!A:E,5,FALSE) -> 3 | E12: =VLOOKUP(B12,الجدول!A:D,4,FALSE) -> أ. الشريف الملاح | F12: =VLOOKUP(B12,الجدول!A:D,3,FALSE) -> الخميس 09:00
A13: =[1]Sheet2!A13 -> 5163 | B13: =[1]Sheet2!B13 -> 2811 | C13: =VLOOKUP(B13,الجدول!A:B,2,FALSE) -> Translation Theories and Practice | D13: =VLOOKUP(B13,الجدول!A:E,5,FALSE) -> 3 | E13: =VLOOKUP(B13,الجدول!A:D,4,FALSE) -> أ. علي اغنيوه | F13: =VLOOKUP(B13,الجدول!A:D,3,FALSE) -> السبت 11:00
... A1000: =[1]Sheet2!A1000 -> 0 | B1000: =[1]Sheet2!B1000 -> 0 | C1000: =VLOOKUP(B1000,الجدول!A:B,2,FALSE) -> 0 | D1000: =VLOOKUP(B1000,الجدول!A:E,5,FALSE) -> 0 | E1000: =VLOOKUP(B1000,الجدول!A:D,4,FALSE) -> 0 | F1000: =VLOOKUP(B1000,الجدول!A:D,3,FALSE) -> 0

Sheet السجل الدراسي والنتائج
A1: رقم المقرر | B1: اسم المقرر | C1: الأسبقية | D1: =التحديث!S1 -> الجدول | E1: =التحديث!T1 -> أستاذ المادة | F1: حالة امقرر | G1: =التحديث!V1 -> 1 | H1: =التحديث!W1 -> 2 | I1: =التحديث!X1 -> 3 | J1: =التحديث!Y1 -> 4 | K1: =التحديث!Z1 -> 5 | L1: =التحديث!AA1 -> 6 | M1: =التحديث!AB1 -> 7 | N1: =التحديث!AC1 -> 8 | ... BAC1: =التحديث!BAR1 -> 0
A2: 0 | B2: الفصل الأول | F2: =التحديث!U2 -> 0 | G2: =التحديث!V2 -> 1937 | H2: =التحديث!W2 -> 2114 | I2: =التحديث!X2 -> 2123 | J2: =التحديث!Y2 -> 2128 | K2: =التحديث!Z2 -> 2133 | L2: =التحديث!AA2 -> 2137 | M2: =التحديث!AB2 -> 2156 | ... BAC2: =التحديث!BAR2 -> 0
A3: =التحديث!Q3 -> 100 | B3: =التحديث!R3 -> اللغة العربية | D3: =التحديث!S3 -> الثلاثاء 11:00 | E3: =التحديث!T3 -> أ. سالم علي | F3: =التحديث!U3 -> 0 | G3: =التحديث!V3 -> 1 | H3: =التحديث!W3 -> 1 | I3: =التحديث!X3 -> 1 | J3: =التحديث!Y3 -> 1 | K3: =التحديث!Z3 -> 1 | ... BAC3: =التحديث!BAR3 -> 0
A4: =التحديث!Q4 -> 2111 | B4: =التحديث!R4 -> Listening and Speaking A | D4: =التحديث!S4 -> الإثنين 11:00 | E4: =التحديث!T4 -> أ. يونس مصطفى | F4: =التحديث!U4 -> 0 | G4: =التحديث!V4 -> 1 | H4: =التحديث!W4 -> 1 | I4: =التحديث!X4 -> 1 | J4: =التحديث!Y4 -> 1 | K4: =التحديث!Z4 -> 1 | ... BAC4: =التحديث!BAR4 -> 0
A5: =التحديث!Q5 -> 2112 | B5: =التحديث!R5 -> Reading Comprehension A | D5: =التحديث!S5 -> الإثنين 09:00 | E5: =التحديث!T5 -> أ. يونس مصطفى | F5: =التحديث!U5 -> 0 | G5: =التحديث!V5 -> 1 | H5: =التحديث!W5 -> 1 | I5: =التحديث!X5 -> 1 | J5: =التحديث!Y5 -> 1 | K5: =التحديث!Z5 -> 1 | ... BAC5: =التحديث!BAR5 -> 0
A6: =التحديث!Q6 -> 2113 | B6: =التحديث!R6 -> Writing A | D6: =التحديث!S6 -> السبت 11:00 | E6: =التحديث!T6 -> أ. فرج مالك | F6: =التحديث!U6 -> 0 | G6: =التحديث!V6 -> 1 | H6: =التحديث!W6 -> 1 | I6: =التحديث!X6 -> 1 | J6: =التحديث!Y6 -> 1 | K6: =التحديث!Z6 -> 1 | ... BAC6: =التحديث!BAR6 -> 0
A7: =التحديث!Q7 -> 2114 | B7: =التحديث!R7 -> English Grammar A | D7: =التحديث!S7 -> الخميس 11:00 | E7: =التحديث!T7 -> أ. الشريف الملاح | F7: =التحديث!U7 -> 0 | G7: =التحديث!V7 -> 1 | H7: =التحديث!W7 -> 1 | I7: =التحديث!X7 -> 1 | J7: =التحديث!Y7 -> 1 | K7: =التحديث!Z7 -> 1 | ... BAC7: =التحديث!BAR7 -> 0
A8: =التحديث!Q13 -> 0 | B8: =التحديث!R13 -> الفصل الثاني | D8: =التحديث!S13 | E8: =التحديث!T13 | F8: =التحديث!U13 -> 0 | G8: =التحديث!V13 -> 0 | H8: =التحديث!W13 -> 0 | I8: =التحديث!X13 -> 0 | J8: =التحديث!Y13 -> 0 | K8: =التحديث!Z13 -> 0 | ... BAC8: =التحديث!BAR13 -> 0
A9: =التحديث!Q14 -> 2305 | B9: =التحديث!R14 -> Listening and Speaking B | C9: 2111 | D9: =التحديث!S14 | E9: =التحديث!T14 -> 0 | F9: =التحديث!U14 -> 0 | G9: =التحديث!V14 -> 1 | H9: =التحديث!W14 -> 1 | I9: =التحديث!X14 -> 1 | J9: =التحديث!Y14 -> 1 | K9: =التحديث!Z14 -> 0 | ... BAC9: =التحديث!BAR14 -> 0
A10: =التحديث!Q15 -> 2302 | B10: =التحديث!R15 -> Reading Comprehension B | C10: 2112 | D10: =التحديث!S15 | E10: =التحديث!T15 -> 0 | F10: =التحديث!U15 -> 0 | G10: =التحديث!V15 -> 1 | H10: =التحديث!W15 -> 1 | I10: =التحديث!X15 -> 1 | J10: =التحديث!Y15 -> 0 | K10: =التحديث!Z15 -> 0 | ... BAC10: =التحديث!BAR15 -> 0
A11: =التحديث!Q16 -> 2303 | B11: =التحديث!R16 -> Writing B | C11: 2113 | D11: =التحديث!S16 -> السبت 09:00 | E11: =التحديث!T16 -> أ. خديجة العشيبي | F11: =التحديث!U16 -> 0 | G11: =التحديث!V16 -> 0 | H11: =التحديث!W16 -> 1 | I11: =التحديث!X16 -> 1 | J11: =التحديث!Y16 -> 0 | K11: =التحديث!Z16 -> 0 | ... BAC11: =التحديث!BAR16 -> 0
A12: =التحديث!Q17 -> 2304 | B12: =التحديث!R17 -> English Grammar B | C12: 2114 | D12: =التحديث!S17 -> الإربعاء 09:00 | E12: =التحديث!T17 -> د. عبدالسلام الرقاص | F12: =التحديث!U17 -> 0 | G12: =التحديث!V17 -> 0 | H12: =التحديث!W17 -> 1 | I12: =التحديث!X17 -> 1 | J12: =التحديث!Y17 -> 0 | K12: =التحديث!Z17 -> 0 | ... BAC12: =التحديث!BAR17 -> 0
A13: =التحديث!Q18 -> 2201 | B13: =التحديث!R18 -> Pronunciation | D13: =التحديث!S18 | E13: =التحديث!T18 -> 0 | F13: =التحديث!U18 -> 0 | G13: =التحديث!V18 -> 1 | H13: =التحديث!W18 -> 1 | I13: =التحديث!X18 -> 1 | J13: =التحديث!Y18 -> 1 | K13: =التحديث!Z18 -> 0 | ... BAC13: =التحديث!BAR18 -> 0
A14: =التحديث!Q25 -> 0 | B14: =التحديث!R25 -> الفصل الثالث | D14: =التحديث!S25 | E14: =التحديث!T25 | F14: =التحديث!U25 -> 0 | G14: =التحديث!V25 -> 0 | H14: =التحديث!W25 -> 0 | I14: =التحديث!X25 -> 0 | J14: =التحديث!Y25 -> 0 | K14: =التحديث!Z25 -> 0 | ... BAC14: =التحديث!BAR25 -> 0
A15: =التحديث!Q26 -> 1102 | B15: =التحديث!R26 -> التطبيقات اللغوية | C15: 100 | D15: =التحديث!S26 -> الثلاثاء 09:00 | E15: =التحديث!T26 -> أ. سالم علي | F15: =التحديث!U26 -> 0 | G15: =التحديث!V26 -> 1 | H15: =التحديث!W26 -> 1 | I15: =التحديث!X26 -> 1 | J15: =التحديث!Y26 -> 1 | K15: =التحديث!Z26 -> 0 | ... BAC15: =التحديث!BAR26 -> 0
A16: =التحديث!Q27 -> 2311 | B16: =التحديث!R27 -> Listening and Speaking C | C16: 2305 | D16: =التحديث!S27 -> الخميس 09:00 | E16: =التحديث!T27 -> أ. آية ثابت | F16: =التحديث!U27 -> 0 | G16: =التحديث!V27 -> 0 | H16: =التحديث!W27 -> 1 | I16: =التحديث!X27 -> 0 | J16: =التحديث!Y27 -> 0 | K16: =التحديث!Z27 -> 0 | ... BAC16: =التحديث!BAR27 -> 0
A17: =التحديث!Q28 -> 2402 | B17: =التحديث!R28 -> Reading Comprehension C | C17: 2302 | D17: =التحديث!S28 -> الإثنين 01:00 | E17: =التحديث!T28 -> أ. يونس مصطفى | F17: =التحديث!U28 -> 0 | G17: =التحديث!V28 -> 0 | H17: =التحديث!W28 -> 1 | I17: =التحديث!X28 -> 0 | J17: =التحديث!Y28 -> 0 | K17: =التحديث!Z28 -> 0 | ... BAC17: =التحديث!BAR28 -> 0
A18: =التحديث!Q29 -> 2313 | B18: =التحديث!R29 -> Academic Writing | C18: 2303 | D18: =التحديث!S29 -> الإربعاء 11:00 | E18: =التحديث!T29 -> د. عبدالسلام الرقاص | F18: =التحديث!U29 -> 0 | G18: =التحديث!V29 -> 0 | H18: =التحديث!W29 -> 1 | I18: =التحديث!X29 -> 0 | J18: =التحديث!Y29 -> 0 | K18: =التحديث!Z29 -> 0 | ... BAC18: =التحديث!BAR29 -> 0
A19: =التحديث!Q30 -> 2504 | B19: =التحديث!R30 -> English Grammar C | C19: 2304 | D19: =التحديث!S30 -> الإثنين 09:00 | E19: =التحديث!T30 -> أ. أسامة سعد | F19: =التحديث!U30 -> 0 | G19: =التحديث!V30 -> 0 | H19: =التحديث!W30 -> 1 | I19: =التحديث!X30 -> 1 | J19: =التحديث!Y30 -> 0 | K19: =التحديث!Z30 -> 0 | ... BAC19: =التحديث!BAR30 -> 0
A20: =التحديث!Q36 -> 0 | B20: =التحديث!R36 -> الفصل الرابع | D20: =التحديث!S36 | E20: =التحديث!T36 | F20: =التحديث!U36 -> 0 | G20: =التحديث!V36 -> 0 | H20: =التحديث!W36 -> 0 | I20: =التحديث!X36 -> 0 | J20: =التحديث!Y36 -> 0 | K20: =التحديث!Z36 -> 0 | ... BAC20: =التحديث!BAR36 -> 0
A21: =التحديث!Q37 -> 2301 | B21: =التحديث!R37 -> Introduction to Linguistics | D21: =التحديث!S37 -> الأحد 09:00 | E21: =التحديث!T37 -> أ. الشريف الملاح | F21: =التحديث!U37 -> 0 | G21: =التحديث!V37 -> 1 | H21: =التحديث!W37 -> 1 | I21: =التحديث!X37 -> 0 | J21: =التحديث!Y37 -> 0 | K21: =التحديث!Z37 -> 0 | ... BAC21: =التحديث!BAR37 -> 0
A22: =التحديث!Q38 -> 2404 | B22: =التحديث!R38 -> Introduction to Translation | C22: 1102 | D22: =التحديث!S38 | E22: =التحديث!T38 -> 0 | F22: =التحديث!U38 -> 0 | G22: =التحديث!V38 -> 0 | H22: =التحديث!W38 -> 1 | I22: =التحديث!X38 -> 1 | J22: =التحديث!Y38 -> 0 | K22: =التحديث!Z38 -> 0 | ... BAC22: =التحديث!BAR38 -> 0
A23: =التحديث!Q39 -> 2202 | B23: =التحديث!R39 -> Introduction to English Literature | D23: =التحديث!S39 | E23: =التحديث!T39 -> 0 | F23: =التحديث!U39 -> 0 | G23: =التحديث!V39 -> 1 | H23: =التحديث!W39 -> 1 | I23: =التحديث!X39 -> 0 | J23: =التحديث!Y39 -> 1 | K23: =التحديث!Z39 -> 1 | ... BAC23: =التحديث!BAR39 -> 0
A24: =التحديث!Q40 -> 3110 | B24: =التحديث!R40 -> الحضارة العربية الإسلامية | D24: =التحديث!S40 -> الثلاثاء 11:00 | E24: =التحديث!T40 -> 0 | F24: =التحديث!U40 -> 0 | G24: =التحديث!V40 -> 1 | H24: =التحديث!W40 -> 1 | I24: =التحديث!X40 -> 1 | J24: =التحديث!Y40 -> 1 | K24: =التحديث!Z40 -> 0 | ... BAC24: =التحديث!BAR40 -> 0
A25: =التحديث!Q41 -> 10101 | B25: =التحديث!R41 -> علم النفس العام | D25: =التحديث!S41 -> الأحد 11:00 | E25: =التحديث!T41 -> 0 | F25: =التحديث!U41 -> 0 | G25: =التحديث!V41 -> 1 | H25: =التحديث!W41 -> 1 | I25: =التحديث!X41 -> 1 | J25: =التحديث!Y41 -> 1 | K25: =التحديث!Z41 -> 1 | ... BAC25: =التحديث!BAR41 -> 0
A26: =التحديث!Q47 -> 0 | B26: =التحديث!R47 -> الفصل الخامس | D26: =التحديث!S47 | E26: =التحديث!T47 | F26: =التحديث!U47 -> 0 | G26: =التحديث!V47 -> 0 | H26: =التحديث!W47 -> 0 | I26: =التحديث!X47 -> 0 | J26: =التحديث!Y47 -> 0 | K26: =التحديث!Z47 -> 0 | ... BAC26: =التحديث!BAR47 -> 0
A27: =التحديث!Q48 -> 2401 | B27: =التحديث!R48 -> Literary Readings A | C27: 2202 | D27: =التحديث!S48 -> السبت 01:00 | E27: =التحديث!T48 -> أ. فرج مالك | F27: =التحديث!U48 -> 0 | G27: =التحديث!V48 -> 0 | H27: =التحديث!W48 -> 1 | I27: =التحديث!X48 -> 0 | J27: =التحديث!Y48 -> 0 | K27: =التحديث!Z48 -> 0 | ... BAC27: =التحديث!BAR48 -> 0
A28: =التحديث!Q49 -> 2512 | B28: =التحديث!R49 -> Phonetics and Phonology | C28: 2301 | D28: =التحديث!S49 -> الخميس 09:00 | E28: =التحديث!T49 -> أ. الشريف الملاح | F28: =التحديث!U49 -> 0 | G28: =التحديث!V49 -> 0 | H28: =التحديث!W49 -> 1 | I28: =التحديث!X49 -> 0 | J28: =التحديث!Y49 -> 0 | K28: =التحديث!Z49 -> 0 | ... BAC28: =التحديث!BAR49 -> 0
A29: =التحديث!Q50 -> 2513 | B29: =التحديث!R50 -> Language Acquisition | D29: =التحديث!S50 -> الخميس 11:00 | E29: =التحديث!T50 -> أ. آية ثابت | F29: =التحديث!U50 -> 0 | G29: =التحديث!V50 -> 0 | H29: =التحديث!W50 -> 0 | I29: =التحديث!X50 -> 1 | J29: =التحديث!Y50 -> 0 | K29: =التحديث!Z50 -> 0 | ... BAC29: =التحديث!BAR50 -> 0
A30: =التحديث!Q51 -> 2514 | B30: =التحديث!R51 -> English / Arabic Translation | C30: 2404 | D30: =التحديث!S51 -> السبت 09:00 | E30: =التحديث!T51 -> أ. علي اغنيوه | F30: =التحديث!U51 -> 0 | G30: =التحديث!V51 -> 0 | H30: =التحديث!W51 -> 1 | I30: =التحديث!X51 -> 1 | J30: =التحديث!Y51 -> 0 | K30: =التحديث!Z51 -> 0 | ... BAC30: =التحديث!BAR51 -> 0
A31: =التحديث!Q52 -> 2515 | B31: =التحديث!R52 -> Psycho. Linguistics | C31: 2301 | D31: =التحديث!S52 -> السبت 11:00 | E31: =التحديث!T52 -> أ. خديجة العشيبي | F31: =التحديث!U52 -> 0 | G31: =التحديث!V52 -> 0 | H31: =التحديث!W52 -> 0 | I31: =التحديث!X52 -> 0 | J31: =التحديث!Y52 -> 0 | K31: =التحديث!Z52 -> 0 | ... BAC31: =التحديث!BAR52 -> 0
A32: =التحديث!Q58 -> 0 | B32: =التحديث!R58 -> الفصل السادس | D32: =التحديث!S58 | E32: =التحديث!T58 | F32: =التحديث!U58 -> 0 | G32: =التحديث!V58 -> 0 | H32: =التحديث!W58 -> 0 | I32: =التحديث!X58 -> 0 | J32: =التحديث!Y58 -> 0 | K32: =التحديث!Z58 -> 0 | ... BAC32: =التحديث!BAR58 -> 0
A33: =التحديث!Q59 -> 2701 | B33: =التحديث!R59 -> Teaching Methodology and Strategies | C33: 2513 | D33: =التحديث!S59 | E33: =التحديث!T59 -> 0 | F33: =التحديث!U59 -> 0 | G33: =التحديث!V59 -> 0 | H33: =التحديث!W59 -> 0 | I33: =التحديث!X59 -> 0 | J33: =التحديث!Y59 -> 0 | K33: =التحديث!Z59 -> 0 | ... BAC33: =التحديث!BAR59 -> 0
A34: =التحديث!Q60 -> 2502 | B34: =التحديث!R60 -> Literary Readings B | C34: 2401 | D34: =التحديث!S60 | E34: =التحديث!T60 -> 0 | F34: =التحديث!U60 -> 0 | G34: =التحديث!V60 -> 0 | H34: =التحديث!W60 -> 0 | I34: =التحديث!X60 -> 0 | J34: =التحديث!Y60 -> 0 | K34: =التحديث!Z60 -> 0 | ... BAC34: =التحديث!BAR60 -> 0
A35: =التحديث!Q61 -> 2603 | B35: =التحديث!R61 -> Introduction to ESP | C35: 2513 | D35: =التحديث!S61 -> السبت 01:00 | E35: =التحديث!T61 -> أ. خديجة العشيبي | F35: =التحديث!U61 -> 0 | G35: =التحديث!V61 -> 0 | H35: =التحديث!W61 -> 0 | I35: =التحديث!X61 -> 0 | J35: =التحديث!Y61 -> 0 | K35: =التحديث!Z61 -> 0 | ... BAC35: =التحديث!BAR61 -> 0
A36: =التحديث!Q62 -> 2614 | B36: =التحديث!R62 -> Lexicography | C36: 0 | D36: =التحديث!S62 -> السبت 09:00 | E36: =التحديث!T62 -> أ. فرج مالك | F36: =التحديث!U62 -> 0 | G36: =التحديث!V62 -> 0 | H36: =التحديث!W62 -> 0 | I36: =التحديث!X62 -> 0 | J36: =التحديث!Y62 -> 0 | K36: =التحديث!Z62 -> 0 | ... BAC36: =التحديث!BAR62 -> 0
A37: =التحديث!Q63 -> 2615 | B37: =التحديث!R63 -> Arabic / English Translation | C37: 2514 | D37: =التحديث!S63 | E37: =التحديث!T63 -> 0 | F37: =التحديث!U63 -> 0 | G37: =التحديث!V63 -> 0 | H37: =التحديث!W63 -> 1 | I37: =التحديث!X63 -> 0 | J37: =التحديث!Y63 -> 0 | K37: =التحديث!Z63 -> 0 | ... BAC37: =التحديث!BAR63 -> 0
A38: =التحديث!Q69 -> 0 | B38: =التحديث!R69 -> الفصل السابع | D38: =التحديث!S69 | E38: =التحديث!T69 | F38: =التحديث!U69 -> 0 | G38: =التحديث!V69 -> 0 | H38: =التحديث!W69 -> 0 | I38: =التحديث!X69 -> 0 | J38: =التحديث!Y69 -> 0 | K38: =التحديث!Z69 -> 0 | ... BAC38: =التحديث!BAR69 -> 0
A39: =التحديث!Q70 -> 2711 | B39: =التحديث!R70 -> Introduction to Syllabus Design | C39: 2701 | D39: =التحديث!S70 | E39: =التحديث!T70 -> 0 | F39: =التحديث!U70 -> 0 | G39: =التحديث!V70 -> 0 | H39: =التحديث!W70 -> 0 | I39: =التحديث!X70 -> 0 | J39: =التحديث!Y70 -> 0 | K39: =التحديث!Z70 -> 0 | ... BAC39: =التحديث!BAR70 -> 0
A40: =التحديث!Q71 -> 2703 | B40: =التحديث!R71 -> Research Methodology | C40: 2313 | D40: =التحديث!S71 -> الخميس 11:00 | E40: =التحديث!T71 -> أ. فرج الجارح | F40: =التحديث!U71 -> 0 | G40: =التحديث!V71 -> 0 | H40: =التحديث!W71 -> 0 | I40: =التحديث!X71 -> 0 | J40: =التحديث!Y71 -> 0 | K40: =التحديث!Z71 -> 0 | ... BAC40: =التحديث!BAR71 -> 0
...

Sheet بيانات الطلبة
A1: الرقم الجامعي | B1: اسم الطالب | C1: البرنامج | D1: الحالة
A2: =التحديث!O2 -> 4800 | B2: =التحديث!P2 -> أسماء يوسف حمد | C2: اللغة الانجليزية | D2: منتظم
A3: =التحديث!O3 -> 4808 | B3: =التحديث!P3 -> يوسف عبد المنعم أحمد سرحان | C3: اللغة الانجليزية | D3: منتظم
A4: =التحديث!O4 -> 4811 | B4: =التحديث!P4 -> ندى مفتاح حمد | C4: اللغة الانجليزية | D4: منتظم
A5: =التحديث!O5 -> 5163 | B5: =التحديث!P5 -> سماح فتاح جيدالله سعد | C5: اللغة الانجليزية | D5: منتظم
A6: =التحديث!O6 -> 5183 | B6: =التحديث!P6 -> عائشة سعد لطفي | C6: اللغة الانجليزية | D6: منتظم
A7: =التحديث!O7 -> 5219 | B7: =التحديث!P7 -> فاطمة عمر امعزب | C7: اللغة الانجليزية | D7: منتظم
A8: =التحديث!O8 -> 5249 | B8: =التحديث!P8 -> هاجر عبدالجليل محمد صالح | C8: اللغة الانجليزية | D8: منتظم
A9: =التحديث!O9 -> 5251 | B9: =التحديث!P9 -> وداد عبدالسلام مختار محمد | C9: اللغة الانجليزية | D9: منتظم
A10: =التحديث!O10 -> 5263 | B10: =التحديث!P10 -> محمد يونس محمد بوسيف | C10: اللغة الانجليزية | D10: منتظم
A11: =التحديث!O11 -> 5271 | B11: =التحديث!P11 -> سلوى الصالحين موسى | C11: اللغة الانجليزية | D11: منتظم
A12: =التحديث!O12 -> 5277 | B12: =التحديث!P12 -> مبروكة بشير صالح محمد | C12: اللغة الانجليزية | D12: منتظم
A13: =التحديث!O13 -> 5460 | B13: =التحديث!P13 -> أروى يوسف سعد الطالب | C13: اللغة الانجليزية | D13: منتظم
... A700: =التحديث!O700 -> 0 | B700: =التحديث!P700 -> 0 | C700: اللغة الانجليزية | D700: منتظم

Sheet الجدول
A1: 444 | B1: 0 | C1: الجدول | D1: أستاذ المادة | E1: الوحدات
A2: =التحديث!K2 -> 0 | B2: =التحديث!L2 -> 0 | C2: =التحديث!M2 -> 0 | D2: =التحديث!N2 -> 0
A3: =التحديث!K3 -> 100 | B3: =التحديث!L3 -> اللغة العربية | C3: =التحديث!M3 -> الثلاثاء 11:00 | D3: =التحديث!N3 -> أ. سالم علي | E3: 3
A4: =التحديث!K4 -> 2111 | B4: =التحديث!L4 -> Listening and Speaking A | C4: =التحديث!M4 -> الإثنين 11:00 | D4: =التحديث!N4 -> أ. يونس مصطفى | E4: 4
A5: =التحديث!K5 -> 2112 | B5: =التحديث!L5 -> Reading Comprehension A | C5: =التحديث!M5 -> الإثنين 09:00 | D5: =التحديث!N5 -> أ. يونس مصطفى | E5: 3
A6: =التحديث!K6 -> 2113 | B6: =التحديث!L6 -> Writing A | C6: =التحديث!M6 -> السبت 11:00 | D6: =التحديث!N6 -> أ. فرج مالك | E6: 3
A7: =التحديث!K7 -> 2114 | B7: =التحديث!L7 -> English Grammar A | C7: =التحديث!M7 -> الخميس 11:00 | D7: =التحديث!N7 -> أ. الشريف الملاح | E7: 3
A8: =التحديث!K8 -> 0 | B8: =التحديث!L8 -> 0 | C8: =التحديث!M8 | D8: =التحديث!N8
A9: =التحديث!K9 -> 0 | B9: =التحديث!L9 -> 0 | C9: =التحديث!M9 | D9: =التحديث!N9
A10: =التحديث!K10 -> 0 | B10: =التحديث!L10 -> 0 | C10: =التحديث!M10 | D10: =التحديث!N10
A11: =التحديث!K11 -> 0 | B11: =التحديث!L11 -> 0 | C11: =التحديث!M11 | D11: =التحديث!N11
A12: =التحديث!K12 -> 0 | B12: =التحديث!L12 -> 0 | C12: =التحديث!M12 | D12: =التحديث!N12
A13: =التحديث!K13 -> 0 | B13: =التحديث!L13 -> الفصل الثاني | C13: =التحديث!M13 | D13: =التحديث!N13
A14: =التحديث!K14 -> 2305 | B14: =التحديث!L14 -> Listening and Speaking B | C14: =التحديث!M14 | D14: =التحديث!N14 -> 0 | E14: 4
A15: =التحديث!K15 -> 2302 | B15: =التحديث!L15 -> Reading Comprehension B | C15: =التحديث!M15 | D15: =التحديث!N15 -> 0 | E15: 3
A16: =التحديث!K16 -> 2303 | B16: =التحديث!L16 -> Writing B | C16: =التحديث!M16 -> السبت 09:00 | D16: =التحديث!N16 -> أ. خديجة العشيبي | E16: 3
A17: =التحديث!K17 -> 2304 | B17: =التحديث!L17 -> English Grammar B | C17: =التحديث!M17 -> الإربعاء 09:00 | D17: =التحديث!N17 -> د. عبدالسلام الرقاص | E17: 3
A18: =التحديث!K18 -> 2201 | B18: =التحديث!L18 -> Pronunciation | C18: =التحديث!M18 | D18: =التحديث!N18 -> 0 | E18: 3
A19: =التحديث!K19 -> 0 | B19: =التحديث!L19 -> 0 | C19: =التحديث!M19 | D19: =التحديث!N19
A20: =التحديث!K20 -> 0 | B20: =التحديث!L20 -> 0 | C20: =التحديث!M20 | D20: =التحديث!N20
A21: =التحديث!K21 -> 0 | B21: =التحديث!L21 -> 0 | C21: =التحديث!M21 | D21: =التحديث!N21
A22: =التحديث!K22 -> 0 | B22: =التحديث!L22 -> 0 | C22: =التحديث!M22 | D22: =التحديث!N22
A23: =التحديث!K23 -> 0 | B23: =التحديث!L23 -> 0 | C23: =التحديث!M23 | D23: =التحديث!N23
A24: =التحديث!K24 -> 0 | B24: =التحديث!L24 -> 0 | C24: =التحديث!M24 | D24: =التحديث!N24
A25: =التحديث!K25 -> 0 | B25: =التحديث!L25 -> الفصل الثالث | C25: =التحديث!M25 | D25: =التحديث!N25
A26: =التحديث!K26 -> 1102 | B26: =التحديث!L26 -> التطبيقات اللغوية | C26: =التحديث!M26 -> الثلاثاء 09:00 | D26: =التحديث!N26 -> أ. سالم علي | E26: 3
A27: =التحديث!K27 -> 2311 | B27: =التحديث!L27 -> Listening and Speaking C | C27: =التحديث!M27 -> الخميس 09:00 | D27: =التحديث!N27 -> أ. آية ثابت | E27: 4
A28: =التحديث!K28 -> 2402 | B28: =التحديث!L28 -> Reading Comprehension C | C28: =التحديث!M28 -> الإثنين 01:00 | D28: =التحديث!N28 -> أ. يونس مصطفى | E28: 3
A29: =التحديث!K29 -> 2313 | B29: =التحديث!L29 -> Academic Writing | C29: =التحديث!M29 -> الإربعاء 11:00 | D29: =التحديث!N29 -> د. عبدالسلام الرقاص | E29: 4
A30: =التحديث!K30 -> 2504 | B30: =التحديث!L30 -> English Grammar C | C30: =التحديث!M30 -> الإثنين 09:00 | D30: =التحديث!N30 -> أ. أسامة سعد | E30: 3
A31: =التحديث!K31 -> 0 | B31: =التحديث!L31 -> 0 | C31: =التحديث!M31 | D31: =التحديث!N31
A32: =التحديث!K32 -> 0 | B32: =التحديث!L32 -> 0 | C32: =التحديث!M32 | D32: =التحديث!N32
A33: =التحديث!K33 -> 0 | B33: =التحديث!L33 -> 0 | C33: =التحديث!M33 | D33: =التحديث!N33
A34: =التحديث!K34 -> 0 | B34: =التحديث!L34 -> 0 | C34: =التحديث!M34 | D34: =التحديث!N34
A35: =التحديث!K35 -> 0 | B35: =التحديث!L35 -> 0 | C35: =التحديث!M35 | D35: =التحديث!N35
A36: =التحديث!K36 -> 0 | B36: =التحديث!L36 -> الفصل الرابع | C36: =التحديث!M36 | D36: =التحديث!N36
A37: =التحديث!K37 -> 2301 | B37: =التحديث!L37 -> Introduction to Linguistics | C37: =التحديث!M37 -> الأحد 09:00 | D37: =التحديث!N37 -> أ. الشريف الملاح | E37: 4
A38: =التحديث!K38 -> 2404 | B38: =التحديث!L38 -> Introduction to Translation | C38: =التحديث!M38 | D38: =التحديث!N38 -> 0 | E38: 4
A39: =التحديث!K39 -> 2202 | B39: =التحديث!L39 -> Introduction to English Literature | C39: =التحديث!M39 | D39: =التحديث!N39 -> 0 | E39: 3
A40: =التحديث!K40 -> 3110 | B40: =التحديث!L40 -> الحضارة العربية الإسلامية | C40: =التحديث!M40 -> الثلاثاء 11:00 | D40: =التحديث!N40 -> 0 | E40: 3
...

Sheet التحديث
A1: student ID | B1: 1st | C1: 2nd | D1: 3rd | E1: 4th | F1: 5th | G1: 6th | H1: 7th | K1: 0 | L1: 0 | M1: الجدول | N1: أستاذ المادة | O1: الرقم الدراسي | P1: الاسم | Q1: 0 | R1: 0 | S1: الجدول | T1: أستاذ المادة | U1: بحث | V1: 1 | W1: 2 | X1: 3 | Y1: 4 | Z1: 5 | AA1: 6 | AB1: 7 | AC1: 8 | AD1: 9 | AE1: 10 | AF1: 11 | AG1: 12 | AH1: 13 | AI1: 14 | AJ1: 15 | AK1: 16 | AL1: 17 | AM1: 18 | AN1: 19 | AO1: 20 | AP1: 21 | AQ1: 22 | AR1: 23 | AS1: 24 | AT1: 25 | AU1: 26 | AV1: 27 | AW1: 28 | AX1: 29 | AY1: 30 | AZ1: 31 | BA1: 32 | BB1: 33 | BC1: 34 | BD1: 35 | BE1: 36 | BF1: 37 | BG1: 38 | BH1: 39 | BI1: 40 | BJ1: 41 | BK1: 42 | BL1: 43 | BM1: 44 | BN1: 45 | BO1: 46 | BP1: 47 | BQ1: 48 | BR1: 49 | BS1: 50 | BT1: 51 | BU1: 52 | BV1: 53 | BW1: 54 | BX1: 55 | BY1: 56 | BZ1: 57 | CA1: 58 | CB1: 59 | CC1: 60 | CD1: 61 | CE1: 62 | CF1: 63 | CG1: 64 | CH1: 65 | CI1: 66 | CJ1: 67 | CK1: 68 | CL1: 69 | CM1: 70 | CN1: 71 | CO1: 72 | CP1: 73 | CQ1: 74 | CR1: 75 | CS1: 76 | CT1: 77 | CU1: 78 | CV1: 79 | CW1: 80 | CX1: 81 | CY1: 82 | CZ1: 83 | DA1: 84 | DB1: 85 | DC1: 86 | DD1: 87 | DE1: 88 | DF1: 89 | DG1: 90 | DH1: 91 | DI1: 92 | DJ1: 93 | DK1: 94 | DL1: 95 | DM1: 96 | DN1: 97 | DO1: 98 | DP1: 99 | DQ1: 100 | DR1: 101 | DS1: 102 | DT1: 103 | DU1: 104 | DV1: 105 | DW1: 106 | DX1: 107 | DY1: 108 | DZ1: 109 | EA1: 110 | EB1: 111 | EC1: 112 | ED1: 113 | EE1: 114 | EF1: 115 | EG1: 116 | EH1: 117 | EI1: 118 | EJ1: 119 | EK1: 120 | EL1: 121 | EM1: 122 | EN1: 123 | EO1: 124 | EP1: 125 | EQ1: 126 | ER1: 127 | ES1: 128 | ET1: 129 | EU1: 130 | EV1: 131 | EW1: 132 | EX1: 133 | EY1: 134 | EZ1: 135 | FA1: 136 | FB1: 137 | FC1: 138 | FD1: 139 | FE1: 140 | FF1: 141 | FG1: 142 | FH1: 143 | FI1: 144 | FJ1: 145 | FK1: 146 | FL1: 147 | FM1: 148 | FN1: 149 | FO1: 150 | FP1: 151 | FQ1: 152 | FR1: 153 | FS1: 154 | FT1: 155 | FU1: 156 | FV1: 157 | FW1: 158 | FX1: 159 | FY1: 160 | FZ1: 161 | GA1: 162 | GB1: 163 | GC1: 164 | GD1: 165 | GE1: 166 | GF1: 167 | GG1: 168 | GH1: 169 | GI1: 170 | GJ1: 171 | GK1: 172 | GL1: 173 | GM1: 174 | GN1: 175 | GO1: 176 | GP1: 177 | GQ1: 178 | GR1: 179 | GS1: 180 | GT1: 181 | GU1: 182 | GV1: 183 | GW1: 184 | GX1: 185 | GY1: 186 | GZ1: 187 | HA1: 188 | HB1: 189 | HC1: 190 | HD1: 191 | HE1: 192 | HF1: 193 | HG1: 194 | HH1: 195 | HI1: 196 | HJ1: 197 | HK1: 198 | HL1: 199 | HM1: 200 | HN1: 201 | HO1: 202 | HP1: 203 | HQ1: 204 | HR1: 205 | HS1: 206 | HT1: 207 | HU1: 208 | HV1: 209 | HW1: 210 | HX1: 211 | HY1: 212 | HZ1: 213 | IA1: 214 | IB1: 215 | IC1: 216 | ID1: 217 | IE1: 218 | IF1: 219 | IG1: 220 | IH1: 221 | II1: 222 | IJ1: 223 | IK1: 224 | IL1: 225 | IM1: 226 | IN1: 227 | IO1: 228 | IP1: 229 | IQ1: 230 | IR1: 231 | IS1: 232 | IT1: 233 | IU1: 234 | IV1: 235 | IW1: 236 | IX1: 237 | IY1: 238 | IZ1: 239 | JA1: 240 | JB1: 241 | JC1: 242 | JD1: 243 | JE1: 244 | JF1: 245 | JG1: 246 | JH1: 247 | JI1: 248 | JJ1: 249 | JK1: 250 | JL1: 251 | JM1: 252 | JN1: 253 | JO1: 254 | JP1: 255 | JQ1: 256 | JR1: 257 | JS1: 258 | JT1: 259 | JU1: 260 | JV1: 261 | JW1: 262 | JX1: 263 | JY1: 264 | JZ1: 265 | KA1: 266 | KB1: 267 | KC1: 268 | KD1: 269 | KE1: 270 | KF1: 271 | KG1: 272 | KH1: 273 | KI1: 274 | KJ1: 275 | KK1: 276 | KL1: 277 | KM1: 278 | KN1: 279 | KO1: 280 | KP1: 281 | KQ1: 282 | KR1: 283 | KS1: 284 | KT1: 285 | KU1: 286 | KV1: 287 | KW1: 288 | KX1: 289 | KY1: 290 | KZ1: 291 | LA1: 292 | LB1: 293 | LC1: 294 | LD1: 295 | LE1: 296 | LF1: 297 | LG1: 298 | LH1: 299 | LI1: 300 | LJ1: 301 | LK1: 302 | LL1: 303 | LM1: 304 | LN1: 305 | LO1: 306 | LP1: 307 | LQ1: 308 | LR1: 309 | LS1: 310 | LT1: 311 | LU1: 312 | LV1: 313 | LW1: 314 | LX1: 315 | LY1: 316 | LZ1: 317 | MA1: 318 | MB1: 319 | MC1: 320 | MD1: 321 | ME1: 322 | MF1: 323 | MG1: 324 | MH1: 325 | MI1: 326 | MJ1: 327 | MK1: 328 | ML1: 329 | MM1: 330 | MN1: 331 | MO1: 332 | MP1: 333 | MQ1: 334 | MR1: 335 | MS1: 336 | MT1: 337 | MU1: 338 | MV1: 339 | MW1: 340 | MX1: 341 | MY1: 342 | MZ1: 343 | NA1: 344 | NB1: 345 | NC1: 346 | ND1: 347 | NE1: 348 | NF1: 349 | NG1: 350 | NH1: 351 | NI1: 352 | NJ1: 353 | NK1: 354 | NL1: 355 | NM1: 356 | NN1: 357 | NO1: 358 | NP1: 359 | NQ1: 360 | NR1: 361 | NS1: 362 | NT1: 363 | NU1: 364 | NV1: 365 | NW1: 366 | NX1: 367 | NY1: 368 | NZ1: 369 | OA1: 370 | OB1: 371 | OC1: 372 | OD1: 373 | OE1: 374 | OF1: 375 | OG1: 376 | OH1: 377 | OI1: 378 | OJ1: 379 | OK1: 380 | OL1: 381 | OM1: 382 | ON1: 383 | OO1: 384 | OP1: 385 | OQ1: 386 | OR1: 387 | OS1: 388 | OT1: 389 | OU1: 390 | OV1: 391 | OW1: 392 | OX1: 393 | OY1: 394 | OZ1: 395 | PA1: 396 | PB1: 397 | PC1: 398 | PD1: 399 | PE1: 400 | PF1: 401 | PG1: 402 | PH1: 403 | PI1: 404 | PJ1: 405 | PK1: 406 | PL1: 407 | PM1: 408 | PN1: 409 | PO1: 410 | PP1: 411 | PQ1: 412 | PR1: 413 | PS1: 414 | PT1: 415 | PU1: 416 | PV1: 417 | PW1: 418 | PX1: 419 | PY1: 420 | PZ1: 421 | QA1: 422 | QB1: 423 | QC1: 424 | QD1: 425 | QE1: 426 | QF1: 427 | QG1: 428 | QH1: 429 | QI1: 430 | QJ1: 431 | QK1: 432 | QL1: 433 | QM1: 434 | QN1: 435 | QO1: 436 | QP1: 437 | QQ1: 438 | QR1: 439 | QS1: 440 | QT1: 441 | QU1: 442 | QV1: 443 | QW1: 444 | QX1: 445 | QY1: 446 | QZ1: 447 | RA1: 448 | RB1: 449 | RC1: 450 | RD1: 451 | RE1: 452 | RF1: 453 | RG1: 454 | RH1: 455 | RI1: 456 | RJ1: 457 | RK1: 458 | RL1: 459 | RM1: 460 | RN1: 461 | RO1: 462 | RP1: 463 | RQ1: 464 | RR1: 465 | RS1: 466 | RT1: 467 | RU1: 468 | RV1: 469 | RW1: 470 | RX1: 471 | RY1: 472 | RZ1: 473 | SA1: 474 | SB1: 475 | SC1: 476 | SD1: 477 | SE1: 478 | SF1: 479 | SG1: 480 | SH1: 481 | SI1: 482 | SJ1: 483 | SK1: 484 | SL1: 485 | SM1: 486 | SN1: 487 | SO1: 488 | SP1: 489 | SQ1: 490 | SR1: 491 | SS1: 492 | ST1: 493 | SU1: 494 | SV1: 495 | SW1: 496 | SX1: 497 | SY1: 498 | SZ1: 499 | TA1: 500 | TB1: 501 | TC1: 502 | TD1: 503 | TE1: 504 | TF1: 505 | TG1: 506 | TH1: 507 | TI1: 508 | TJ1: 509 | TK1: 510 | TL1: 511 | TM1: 512 | TN1: 513 | TO1: 514 | TP1: 515 | TQ1: 516 | TR1: 517 | TS1: 518 | TT1: 519 | TU1: 520 | TV1: 521 | TW1: 522 | TX1: 523 | TY1: 524 | TZ1: 525 | UA1: 526 | UB1: 527 | UC1: 528 | UD1: 529 | UE1: 530 | UF1: 531 | UG1: 532 | UH1: 533 | UI1: 534 | UJ1: 535 | UK1: 536 | UL1: 537 | UM1: 538 | UN1: 539 | UO1: 540 | UP1: 541 | UQ1: 542 | UR1: 543 | US1: 544 | UT1: 545 | UU1: 546 | UV1: 547 | UW1: 548 | UX1: 549 | UY1: 550 | UZ1: 551 | VA1: 552 | VB1: 553 | VC1: 554 | VD1: 555 | VE1: 556 | VF1: 557 | VG1: 558 | VH1: 559 | VI1: 560 | VJ1: 561 | VK1: 562 | VL1: 563 | VM1: 564 | VN1: 565 | VO1: 566 | VP1: 567 | VQ1: 568 | VR1: 569 | VS1: 570 | VT1: 571 | VU1: 572 | VV1: 573 | VW1: 574 | VX1: 575 | VY1: 576 | VZ1: 577 | WA1: 578 | WB1: 579 | WC1: 580 | WD1: 581 | WE1: 582 | WF1: 583 | WG1: 584 | WH1: 585 | WI1: 586 | WJ1: 587 | WK1: 588 | WL1: 589 | WM1: 590 | WN1: 591 | WO1: 592 | WP1: 593 | WQ1: 594 | WR1: 595 | WS1: 596 | WT1: 597 | WU1: 598 | WV1: 599 | WW1: 600 | WX1: 601 | WY1: 602 | WZ1: 603 | XA1: 604 | XB1: 605 | XC1: 606 | XD1: 607 | XE1: 608 | XF1: 609 | XG1: 610 | XH1: 611 | XI1: 612 | XJ1: 613 | XK1: 614 | XL1: 615 | XM1: 616 | XN1: 617 | XO1: 618 | XP1: 619 | XQ1: 620 | XR1: 621 | XS1: 622 | XT1: 623 | XU1: 624 | XV1: 625 | XW1: 626 | XX1: 627 | XY1: 628 | XZ1: 629 | YA1: 630 | YB1: 631 | YC1: 632 | YD1: 633 | YE1: 634 | YF1: 635 | YG1: 636 | YH1: 637 | YI1: 638 | YJ1: 639 | YK1: 640 | YL1: 641 | YM1: 642 | YN1: 643 | YO1: 644 | YP1: 645 | YQ1: 646 | YR1: 647 | YS1: 648 | YT1: 649 | YU1: 650 | YV1: 651 | YW1: 652 | YX1: 653 | YY1: 654 | YZ1: 655 | ZA1: 656 | ZB1: 657 | ZC1: 658 | ZD1: 659 | ZE1: 660 | ZF1: 661 | ZG1: 662 | ZH1: 663 | ZI1: 664 | ZJ1: 665 | ZK1: 666 | ZL1: 667 | ZM1: 668 | ZN1: 669 | ZO1: 670 | ZP1: 671 | ZQ1: 672 | ZR1: 673 | ZS1: 674 | ZT1: 675 | ZU1: 676 | ZV1: 677 | ZW1: 678 | ZX1: 679 | ZY1: 680 | ZZ1: 681 | AAA1: 682 | AAB1: 683 | AAC1: 684 | AAD1: 685 | AAE1: 686 | AAF1: 687 | AAG1: 688 | AAH1: 689 | AAI1: 690 | AAJ1: 691 | AAK1: 692 | AAL1: 693 | AAM1: 694 | AAN1: 695 | AAO1: 696 | AAP1: 697 | AAQ1: 698 | AAR1: 699 | AAS1: 700 | AAT1: 701 | AAU1: 702 | AAV1: 703 | AAW1: 704 | AAX1: 705 | AAY1: 706 | AAZ1: 707 | ABA1: 708 | ABB1: 709 | ABC1: 710 | ABD1: 711 | ABE1: 712 | ABF1: 713 | ABG1: 714 | ABH1: 715 | ABI1: 716 | ABJ1: 717 | ABK1: 718 | ABL1: 719 | ABM1: 720 | ABN1: 721 | ABO1: 722 | ABP1: 723 | ABQ1: 724 | ABR1: 725 | ABS1: 726 | ABT1: 727 | ABU1: 728 | ABV1: 729 | ABW1: 730 | ABX1: 731 | ABY1: 732 | ABZ1: 733 | ACA1: 734 | ACB1: 735 | ACC1: 736 | ACD1: 737 | ACE1: 738 | ACF1: 739 | ACG1: 740 | ACH1: 741 | ACI1: 742 | ACJ1: 743 | ACK1: 744 | ACL1: 745 | ACM1: 746 | ACN1: 747 | ACO1: 748 | ACP1: 749 | ACQ1: 750 | ACR1: 751 | ACS1: 752 | ACT1: 753 | ACU1: 754 | ACV1: 755 | ACW1: 756 | ACX1: 757 | ACY1: 758 | ACZ1: 759 | ADA1: 760 | ADB1: 761 | ADC1: 762 | ADD1: 763 | ADE1: 764 | ADF1: 765 | ADG1: 766 | ADH1: 767 | ADI1: 768 | ADJ1: 769 | ADK1: 770 | ADL1: 771 | ADM1: 772 | ADN1: 773 | ADO1: 774 | ADP1: 775 | ADQ1: 776 | ADR1: 777 | ADS1: 778 | ADT1: 779 | ADU1: 780 | ADV1: 781 | ADW1: 782 | ADX1: 783 | ADY1: 784 | ADZ1: 785 | AEA1: 786 | AEB1: 787 | AEC1: 788 | AED1: 789 | AEE1: 790 | AEF1: 791 | AEG1: 792 | AEH1: 793 | AEI1: 794 | AEJ1: 795 | AEK1: 796 | AEL1: 797 | AEM1: 798 | AEN1: 799 | AEO1: 800 | AEP1: 801 | AEQ1: 802 | AER1: 803 | AES1: 804 | AET1: 805 | AEU1: 806 | AEV1: 807 | AEW1: 808 | AEX1: 809 | AEY1: 810 | AEZ1: 811 | AFA1: 812 | AFB1: 813 | AFC1: 814 | AFD1: 815 | AFE1: 816 | AFF1: 817 | AFG1: 818 | AFH1: 819 | AFI1: 820 | AFJ1: 821 | AFK1: 822 | AFL1: 823 | AFM1: 824 | AFN1: 825 | AFO1: 826 | AFP1: 827 | AFQ1: 828 | AFR1: 829 | AFS1: 830 | AFT1: 831 | AFU1: 832 | AFV1: 833 | AFW1: 834 | AFX1: 835 | AFY1: 836 | AFZ1: 837 | AGA1: 838 | AGB1: 839 | AGC1: 840 | AGD1: 841 | AGE1: 842 | AGF1: 843 | AGG1: 844 | AGH1: 845 | AGI1: 846 | AGJ1: 847 | AGK1: 848 | AGL1: 849 | AGM1: 850 | AGN1: 851 | AGO1: 852 | AGP1: 853 | AGQ1: 854 | AGR1: 855 | AGS1: 856 | AGT1: 857 | AGU1: 858 | AGV1: 859 | AGW1: 860 | AGX1: 861 | AGY1: 862 | AGZ1: 863 | AHA1: 864 | AHB1: 865 | AHC1: 866 | AHD1: 867 | AHE1: 868 | AHF1: 869 | AHG1: 870 | AHH1: 871 | AHI1: 872 | AHJ1: 873 | AHK1: 874 | AHL1: 875 | AHM1: 876 | AHN1: 877 | AHO1: 878 | AHP1: 879 | AHQ1: 880 | AHR1: 881 | AHS1: 882 | AHT1: 883 | AHU1: 884 | AHV1: 885 | AHW1: 886 | AHX1: 887 | AHY1: 888 | AHZ1: 889 | AIA1: 890 | AIB1: 891 | AIC1: 892 | AID1: 893 | AIE1: 894 | AIF1: 895 | AIG1: 896 | AIH1: 897 | AII1: 898 | AIJ1: 899 | AIK1: 900 | AIL1: 901 | AIM1: 902 | AIN1: 903 | AIO1: 904 | AIP1: 905 | AIQ1: 906 | AIR1: 907 | AIS1: 908 | AIT1: 909 | AIU1: 910 | AIV1: 911 | AIW1: 912 | AIX1: 913 | AIY1: 914 | AIZ1: 915 | AJA1: 916 | AJB1: 917 | AJC1: 918 | AJD1: 919 | AJE1: 920 | AJF1: 921 | AJG1: 922 | AJH1: 923 | AJI1: 924 | AJJ1: 925 | AJK1: 926 | AJL1: 927 | AJM1: 928 | AJN1: 929 | AJO1: 930 | AJP1: 931 | AJQ1: 932 | AJR1: 933 | AJS1: 934 | AJT1: 935 | AJU1: 936 | AJV1: 937 | AJW1: 938 | AJX1: 939 | AJY1: 940 | AJZ1: 941 | AKA1: 942 | AKB1: 943 | AKC1: 944 | AKD1: 945 | AKE1: 946 | AKF1: 947 | AKG1: 948 | AKH1: 949 | AKI1: 950 | AKJ1: 951 | AKK1: 952 | AKL1: 953 | AKM1: 954 | AKN1: 955 | AKO1: 956 | AKP1: 957 | AKQ1: 958 | AKR1: 959 | AKS1: 960 | AKT1: 961 | AKU1: 962 | AKV1: 963 | AKW1: 964 | AKX1: 965 | AKY1: 966 | AKZ1: 967 | ALA1: 968 | ALB1: 969 | ALC1: 970 | ALD1: 971 | ALE1: 972 | ALF1: 973 | ALG1: 974 | ALH1: 975 | ALI1: 976 | ALJ1: 977 | ALK1: 978 | ALL1: 979 | ALM1: 980 | ALN1: 981 | ALO1: 982 | ALP1: 983 | ALQ1: 984 | ALR1: 985 | ALS1: 986 | ALT1: 987 | ALU1: 988 | ALV1: 989 | ALW1: 990 | ALX1: 991 | ALY1: 992 | ALZ1: 993 | AMA1: 994 | AMB1: 995 | AMC1: 996 | AMD1: 997 | AME1: 998 | AMF1: 999 | AMG1: 1000 | AMH1: 0 | AMI1: 0 | AMJ1: 0 | AMK1: 0 | AML1: 0 | AMM1: 0 | AMN1: 0 | AMO1: 0 | AMP1: 0 | AMQ1: 0 | AMR1: 0 | AMS1: 0 | AMT1: 0 | AMU1: 0 | AMV1: 0 | AMW1: 0 | AMX1: 0 | AMY1: 0 | AMZ1: 0 | ANA1: 0 | ANB1: 0 | ANC1: 0 | AND1: 0 | ANE1: 0 | ANF1: 0 | ANG1: 0 | ANH1: 0 | ANI1: 0 | ANJ1: 0 | ANK1: 0 | ANL1: 0 | ANM1: 0 | ANN1: 0 | ANO1: 0 | ANP1: 0 | ANQ1: 0 | ANR1: 0 | ANS1: 0 | ANT1: 0 | ANU1: 0 | ANV1: 0 | ANW1: 0 | ANX1: 0 | ANY1: 0 | ANZ1: 0 | AOA1: 0 | AOB1: 0 | AOC1: 0 | AOD1: 0 | AOE1: 0 | AOF1: 0 | AOG1: 0 | AOH1: 0 | AOI1: 0 | AOJ1: 0 | AOK1: 0 | AOL1: 0 | AOM1: 0 | AON1: 0 | AOO1: 0 | AOP1: 0 | AOQ1: 0 | AOR1: 0 | AOS1: 0 | AOT1: 0 | AOU1: 0 | AOV1: 0 | AOW1: 0 | AOX1: 0 | AOY1: 0 | AOZ1: 0 | APA1: 0 | APB1: 0 | APC1: 0 | APD1: 0 | APE1: 0 | APF1: 0 | APG1: 0 | APH1: 0 | API1: 0 | APJ1: 0 | APK1: 0 | APL1: 0 | APM1: 0 | APN1: 0 | APO1: 0 | APP1: 0 | APQ1: 0 | APR1: 0 | APS1: 0 | APT1: 0 | APU1: 0 | APV1: 0 | APW1: 0 | APX1: 0 | APY1: 0 | APZ1: 0 | AQA1: 0 | AQB1: 0 | AQC1: 0 | AQD1: 0 | AQE1: 0 | AQF1: 0 | AQG1: 0 | AQH1: 0 | AQI1: 0 | AQJ1: 0 | AQK1: 0 | AQL1: 0 | AQM1: 0 | AQN1: 0 | AQO1: 0 | AQP1: 0 | AQQ1: 0 | AQR1: 0 | AQS1: 0 | AQT1: 0 | AQU1: 0 | AQV1: 0 | AQW1: 0 | AQX1: 0 | AQY1: 0 | AQZ1: 0 | ARA1: 0 | ARB1: 0 | ARC1: 0 | ARD1: 0 | ARE1: 0 | ARF1: 0 | ARG1: 0 | ARH1: 0 | ARI1: 0 | ARJ1: 0 | ARK1: 0 | ARL1: 0 | ARM1: 0 | ARN1: 0 | ARO1: 0 | ARP1: 0 | ARQ1: 0 | ARR1: 0 | ARS1: 0 | ART1: 0 | ARU1: 0 | ARV1: 0 | ARW1: 0 | ARX1: 0 | ARY1: 0 | ARZ1: 0 | ASA1: 0 | ASB1: 0 | ASC1: 0 | ASD1: 0 | ASE1: 0 | ASF1: 0 | ASG1: 0 | ASH1: 0 | ASI1: 0 | ASJ1: 0 | ASK1: 0 | ASL1: 0 | ASM1: 0 | ASN1: 0 | ASO1: 0 | ASP1: 0 | ASQ1: 0 | ASR1: 0 | ASS1: 0 | AST1: 0 | ASU1: 0 | ASV1: 0 | ASW1: 0 | ASX1: 0 | ASY1: 0 | ASZ1: 0 | ATA1: 0 | ATB1: 0 | ATC1: 0 | ATD1: 0 | ATE1: 0 | ATF1: 0 | ATG1: 0 | ATH1: 0 | ATI1: 0 | ATJ1: 0 | ATK1: 0 | ATL1: 0 | ATM1: 0 | ATN1: 0 | ATO1: 0 | ATP1: 0 | ATQ1: 0 | ATR1: 0 | ATS1: 0 | ATT1: 0 | ATU1: 0 | ATV1: 0 | ATW1: 0 | ATX1: 0 | ATY1: 0 | ATZ1: 0 | AUA1: 0 | AUB1: 0 | AUC1: 0 | AUD1: 0 | AUE1: 0 | AUF1: 0 | AUG1: 0 | AUH1: 0 | AUI1: 0 | AUJ1: 0 | AUK1: 0 | AUL1: 0 | AUM1: 0 | AUN1: 0 | AUO1: 0 | AUP1: 0 | AUQ1: 0 | AUR1: 0 | AUS1: 0 | AUT1: 0 | AUU1: 0 | AUV1: 0 | AUW1: 0 | AUX1: 0 | AUY1: 0 | AUZ1: 0 | AVA1: 0 | AVB1: 0 | AVC1: 0 | AVD1: 0 | AVE1: 0 | AVF1: 0 | AVG1: 0 | AVH1: 0 | AVI1: 0 | AVJ1: 0 | AVK1: 0 | AVL1: 0 | AVM1: 0 | AVN1: 0 | AVO1: 0 | AVP1: 0 | AVQ1: 0 | AVR1: 0 | AVS1: 0 | AVT1: 0 | AVU1: 0 | AVV1: 0 | AVW1: 0 | AVX1: 0 | AVY1: 0 | AVZ1: 0 | AWA1: 0 | AWB1: 0 | AWC1: 0 | AWD1: 0 | AWE1: 0 | AWF1: 0 | AWG1: 0 | AWH1: 0 | AWI1: 0 | AWJ1: 0 | AWK1: 0 | AWL1: 0 | AWM1: 0 | AWN1: 0 | AWO1: 0 | AWP1: 0 | AWQ1: 0 | AWR1: 0 | AWS1: 0 | AWT1: 0 | AWU1: 0 | AWV1: 0 | AWW1: 0 | AWX1: 0 | AWY1: 0 | AWZ1: 0 | AXA1: 0 | AXB1: 0 | AXC1: 0 | AXD1: 0 | AXE1: 0 | AXF1: 0 | AXG1: 0 | AXH1: 0 | AXI1: 0 | AXJ1: 0 | AXK1: 0 | AXL1: 0 | AXM1: 0 | AXN1: 0 | AXO1: 0 | AXP1: 0 | AXQ1: 0 | AXR1: 0 | AXS1: 0 | AXT1: 0 | AXU1: 0 | AXV1: 0 | AXW1: 0 | AXX1: 0 | AXY1: 0 | AXZ1: 0 | AYA1: 0 | AYB1: 0 | AYC1: 0 | AYD1: 0 | AYE1: 0 | AYF1: 0 | AYG1: 0 | AYH1: 0 | AYI1: 0 | AYJ1: 0 | AYK1: 0 | AYL1: 0 | AYM1: 0 | AYN1: 0 | AYO1: 0 | AYP1: 0 | AYQ1: 0 | AYR1: 0 | AYS1: 0 | AYT1: 0 | AYU1: 0 | AYV1: 0 | AYW1: 0 | AYX1: 0 | AYY1: 0 | AYZ1: 0 | AZA1: 0 | AZB1: 0 | AZC1: 0 | AZD1: 0 | AZE1: 0 | AZF1: 0 | AZG1: 0 | AZH1: 0 | AZI1: 0 | AZJ1: 0 | AZK1: 0 | AZL1: 0 | AZM1: 0 | AZN1: 0 | AZO1: 0 | AZP1: 0 | AZQ1: 0 | AZR1: 0 | AZS1: 0 | AZT1: 0 | AZU1: 0 | AZV1: 0 | AZW1: 0 | AZX1: 0 | AZY1: 0 | AZZ1: 0 | BAA1: 0
A2: 4800 | B2: 2804 | K2: 0 | L2: 0 | M2: 0 | N2: 0 | O2: 4800 | P2: أسماء يوسف حمد | Q2: 0 | R2: 0 | S2: 0 | T2: 0 | U2: 0 | V2: 1937 | W2: 2114 | X2: 2123 | Y2: 2128 | Z2: 2133 | AA2: 2137 | AB2: 2156 | AC2: 2333 | AD2: 2364 | AE2: 2388 | AF2: 2391 | AG2: 2408 | AH2: 2415 | AI2: 2485 | AJ2: 2518 | AK2: 2520 | AL2: 2805 | AM2: 2814 | AN2: 2819 | AO2: 2820 | AP2: 2824 | AQ2: 2825 | AR2: 2830 | AS2: 2840 | AT2: 2843 | AU2: 2844 | AV2: 2850 | AW2: 2851 | AX2: 3063 | AY2: 3171 | AZ2: 3387 | BA2: 3389 | BB2: 3392 | BC2: 3397 | BD2: 3399 | BE2: 3402 | BF2: 3403 | BG2: 3409 | BH2: 3410 | BI2: 3411 | BJ2: 3413 | BK2: 3414 | BL2: 3415 | BM2: 3416 | BN2: 3418 | BO2: 3422 | BP2: 3424 | BQ2: 3425 | BR2: 3430 | BS2: 3456 | BT2: 3458 | BU2: 3460 | BV2: 3540 | BW2: 3541 | BX2: 3542 | BY2: 3826 | BZ2: 3958 | CA2: 3959 | CB2: 3960 | CC2: 3961 | CD2: 3963 | CE2: 3964 | CF2: 3965 | CG2: 3966 | CH2: 3967 | CI2: 3969 | CJ2: 3970 | CK2: 3971 | CL2: 3972 | CM2: 3974 | CN2: 3975 | CO2: 3976 | CP2: 3977 | CQ2: 3978 | CR2: 3981 | CS2: 3982 | CT2: 3990 | CU2: 3991 | CV2: 3992 | CW2: 3993 | CX2: 3994 | CY2: 4037 | CZ2: 4039 | DA2: 4130 | DB2: 4137 | DC2: 4182 | DD2: 4183 | DE2: 4184 | DF2: 4189 | DG2: 4191 | DH2: 4230 | DI2: 4231 | DJ2: 4232 | DK2: 4233 | DL2: 2265 | DM2: 2145 | DN2: 764 | DO2: 1015 | DP2: 1404 | DQ2: 1416 | DR2: 1644 | DS2: 3420 | DT2: 3457 | DU2: 2796 | DV2: 1400 | DW2: 2798 | DX2: 3388 | DY2: 4593 | DZ2: 4523 | EA2: 4524 | EB2: 4525 | EC2: 4526 | ED2: 4527 | EE2: 4528 | EF2: 4529 | EG2: 4531 | EH2: 4532 | EI2: 4533 | EJ2: 4534 | EK2: 4535 | EL2: 4536 | EM2: 4537 | EN2: 4538 | EO2: 4539 | EP2: 4540 | EQ2: 4541 | ER2: 4542 | ES2: 4543 | ET2: 4544 | EU2: 4545 | EV2: 4546 | EW2: 4547 | EX2: 4548 | EY2: 4550 | EZ2: 4551 | FA2: 4552 | FB2: 4553 | FC2: 4554 | FD2: 4555 | FE2: 4556 | FF2: 4557 | FG2: 4558 | FH2: 4559 | FI2: 4561 | FJ2: 4562 | FK2: 4563 | FL2: 4581 | FM2: 4620 | FN2: 4619 | FO2: 4640 | FP2: 4651 | FQ2: 4652 | FR2: 2143 | FS2: 1849 | FT2: 2229 | FU2: 4775 | FV2: 2132 | FW2: 4795 | FX2: 4899 | FY2: 4900 | FZ2: 4898 | GA2: 4803 | GB2: 4804 | GC2: 4805 | GD2: 4808 | GE2: 4810 | GF2: 4811 | GG2: 4813 | GH2: 4814 | GI2: 4816 | GJ2: 4843 | GK2: 4844 | GL2: 4845 | GM2: 4807 | GN2: 4802 | GO2: 4812 | GP2: 4794 | GQ2: 4796 | GR2: 4809 | GS2: 4806 | GT2: 4905 | GU2: 4800 | GV2: 4914 | GW2: 4916 | GX2: 4925 | GY2: 5031 | GZ2: 5129 | HA2: 5130 | HB2: 5131 | HC2: 5132 | HD2: 5135 | HE2: 5136 | HF2: 5137 | HG2: 5138 | HH2: 5139 | HI2: 5140 | HJ2: 5141 | HK2: 5134 | HL2: 5157 | HM2: 5158 | HN2: 5160 | HO2: 5159 | HP2: 5162 | HQ2: 5163 | HR2: 5165 | HS2: 5166 | HT2: 5183 | HU2: 5108 | HV2: 5167 | HW2: 5272 | HX2: 5271 | HY2: 5242 | HZ2: 5245 | IA2: 5279 | IB2: 5285 | IC2: 5281 | ID2: 5269 | IE2: 5243 | IF2: 5270 | IG2: 5240 | IH2: 5275 | II2: 5248 | IJ2: 5257 | IK2: 5238 | IL2: 5282 | IM2: 5253 | IN2: 5276 | IO2: 5280 | IP2: 5250 | IQ2: 5277 | IR2: 5256 | IS2: 5268 | IT2: 5266 | IU2: 5260 | IV2: 5239 | IW2: 5263 | IX2: 5261 | IY2: 5244 | IZ2: 5219 | JA2: 5284 | JB2: 5264 | JC2: 5287 | JD2: 5247 | JE2: 5267 | JF2: 5286 | JG2: 5283 | JH2: 5249 | JI2: 5251 | JJ2: 5262 | JK2: 5259 | JL2: 5252 | JM2: 5258 | JN2: 5265 | JO2: 2823 | JP2: 5460 | JQ2: 5542 | JR2: 5652 | JS2: 5653 | JT2: 5654 | JU2: 5655 | JV2: 5650 | JW2: 5576 | JX2: 5581 | JY2: 5582 | JZ2: 5573 | KA2: 5577 | KB2: 5587 | KC2: 5563 | KD2: 5645 | KE2: 5565 | KF2: 5579 | KG2: 5671 | KH2: 5556 | KI2: 5589 | KJ2: 5574 | KK2: 5584 | KL2: 5558 | KM2: 5570 | KN2: 5562 | KO2: 5567 | KP2: 5564 | KQ2: 5557 | KR2: 5651 | KS2: 5586 | KT2: 5667 | KU2: 129 | KV2: 5575 | KW2: 5559 | KX2: 5571 | KY2: 5568 | KZ2: 5561 | LA2: 5572 | LB2: 5566 | LC2: 5578 | LD2: 5580 | LE2: 140 | LF2: 5585 | LG2: 5560 | LH2: 5672 | LI2: 5569 | LJ2: 4351 | LK2: 2270 | LL2: 5690 | LM2: 5691 | LN2: 5692 | LO2: 5693 | LP2: 5694 | LQ2: 5695 | LR2: 5696 | LS2: 5697 | LT2: 5698 | LU2: 5705 | LV2: 5727 | LW2: 5738 | LX2: 5752 | LY2: 5753 | LZ2: 5756 | MA2: 5820 | MB2: 5821 | MC2: 5822 | MD2: 5826 | ME2: 5827 | MF2: 5828 | MG2: 5829 | MH2: 5830 | MI2: 5831 | MJ2: 5832 | MK2: 5833 | ML2: 5840 | MM2: 5841 | MN2: 5871 | MO2: 6017 | MP2: 2118 | MQ2: 6059 | MR2: 5942 | MS2: 5943 | MT2: 5944 | MU2: 5945 | MV2: 5946 | MW2: 5947 | MX2: 5948 | MY2: 5949 | MZ2: 5950 | NA2: 5951 | NB2: 5952 | NC2: 5953 | ND2: 5954 | NE2: 6069 | NF2: 6073 | NG2: 6120 | NH2: 6133 | NI2: 7060 | NJ2: 7001 | NK2: 7102 | NL2: 7062 | NM2: 7101 | NN2: 7009 | NO2: 7061 | NP2: 7003 | NQ2: 7010 | NR2: 7011 | NS2: 7008 | NT2: 7007 | NU2: 7006 | NV2: 7180 | NW2: 7012 | NX2: 7063 | NY2: 7058 | NZ2: 7004 | OA2: 7005 | OB2: 7002 | OC2: 7015 | OD2: 7000 | OE2: 7014 | OF2: 7013 | OG2: 7049 | OH2: 7117 | OI2: 7198 | OJ2: 7204 | OK2: 7206 | OL2: 7207 | OM2: 7242 | ON2: 7254 | OO2: 7278 | OP2: 7352 | OQ2: 7260 | OR2: 7283 | OS2: 7284 | OT2: 7285 | OU2: 7286 | OV2: 7287 | OW2: 7288 | OX2: 7289 | OY2: 7292 | OZ2: 7293 | PA2: 7294 | PB2: 7295 | PC2: 7296 | PD2: 7297 | PE2: 7298 | PF2: 7336 | PG2: 7360 | PH2: 7361 | PI2: 7368 | PJ2: 7388 | PK2: 7389 | PL2: 7400 | PM2: 7401 | PN2: 7412 | PO2: 7416 | PP2: 7417 | PQ2: 7418 | PR2: 7436 | PS2: 7437 | PT2: 7290 | PU2: 7463 | PV2: 7464 | PW2: 7465 | PX2: 7466 | PY2: 7498 | PZ2: 0 | QA2: 0 | QB2: 0 | QC2: 0 | QD2: 0 | QE2: 0 | QF2: 0 | QG2: 0 | QH2: 0 | QI2: 0 | QJ2: 0 | QK2: 0 | QL2: 0 | QM2: 0 | QN2: 0 | QO2: 0 | QP2: 0 | QQ2: 0 | QR2: 0 | QS2: 0 | QT2: 0 | QU2: 0 | QV2: 0 | QW2: 0 | QX2: 0 | QY2: 0 | QZ2: 0 | RA2: 0 | RB2: 0 | RC2: 0 | RD2: 0 | RE2: 0 | RF2: 0 | RG2: 0 | RH2: 0 | RI2: 0 | RJ2: 0 | RK2: 0 | RL2: 0 | RM2: 0 | RN2: 0 | RO2: 0 | RP2: 0 | RQ2: 0 | RR2: 0 | RS2: 0 | RT2: 0 | RU2: 0 | RV2: 0 | RW2: 0 | RX2: 0 | RY2: 0 | RZ2: 0 | SA2: 0 | SB2: 0 | SC2: 0 | SD2: 0 | SE2: 0 | SF2: 0 | SG2: 0 | SH2: 0 | SI2: 0 | SJ2: 0 | SK2: 0 | SL2: 0 | SM2: 0 | SN2: 0 | SO2: 0 | SP2: 0 | SQ2: 0 | SR2: 0 | SS2: 0 | ST2: 0 | SU2: 0 | SV2: 0 | SW2: 0 | SX2: 0 | SY2: 0 | SZ2: 0 | TA2: 0 | TB2: 0 | TC2: 0 | TD2: 0 | TE2: 0 | TF2: 0 | TG2: 0 | TH2: 0 | TI2: 0 | TJ2: 0 | TK2: 0 | TL2: 0 | TM2: 0 | TN2: 0 | TO2: 0 | TP2: 0 | TQ2: 0 | TR2: 0 | TS2: 0 | TT2: 0 | TU2: 0 | TV2: 0 | TW2: 0 | TX2: 0 | TY2: 0 | TZ2: 0 | UA2: 0 | UB2: 0 | UC2: 0 | UD2: 0 | UE2: 0 | UF2: 0 | UG2: 0 | UH2: 0 | UI2: 0 | UJ2: 0 | UK2: 0 | UL2: 0 | UM2: 0 | UN2: 0 | UO2: 0 | UP2: 0 | UQ2: 0 | UR2: 0 | US2: 0 | UT2: 0 | UU2: 0 | UV2: 0 | UW2: 0 | UX2: 0 | UY2: 0 | UZ2: 0 | VA2: 0 | VB2: 0 | VC2: 0 | VD2: 0 | VE2: 0 | VF2: 0 | VG2: 0 | VH2: 0 | VI2: 0 | VJ2: 0 | VK2: 0 | VL2: 0 | VM2: 0 | VN2: 0 | VO2: 0 | VP2: 0 | VQ2: 0 | VR2: 0 | VS2: 0 | VT2: 0 | VU2: 0 | VV2: 0 | VW2: 0 | VX2: 0 | VY2: 0 | VZ2: 0 | WA2: 0 | WB2: 0 | WC2: 0 | WD2: 0 | WE2: 0 | WF2: 0 | WG2: 0 | WH2: 0 | WI2: 0 | WJ2: 0 | WK2: 0 | WL2: 0 | WM2: 0 | WN2: 0 | WO2: 0 | WP2: 0 | WQ2: 0 | WR2: 0 | WS2: 0 | WT2: 0 | WU2: 0 | WV2: 0 | WW2: 0 | WX2: 0 | WY2: 0 | WZ2: 0 | XA2: 0 | XB2: 0 | XC2: 0 | XD2: 0 | XE2: 0 | XF2: 0 | XG2: 0 | XH2: 0 | XI2: 0 | XJ2: 0 | XK2: 0 | XL2: 0 | XM2: 0 | XN2: 0 | XO2: 0 | XP2: 0 | XQ2: 0 | XR2: 0 | XS2: 0 | XT2: 0 | XU2: 0 | XV2: 0 | XW2: 0 | XX2: 0 | XY2: 0 | XZ2: 0 | YA2: 0 | YB2: 0 | YC2: 0 | YD2: 0 | YE2: 0 | YF2: 0 | YG2: 0 | YH2: 0 | YI2: 0 | YJ2: 0 | YK2: 0 | YL2: 0 | YM2: 0 | YN2: 0 | YO2: 0 | YP2: 0 | YQ2: 0 | YR2: 0 | YS2: 0 | YT2: 0 | YU2: 0 | YV2: 0 | YW2: 0 | YX2: 0 | YY2: 0 | YZ2: 0 | ZA2: 0 | ZB2: 0 | ZC2: 0 | ZD2: 0 | ZE2: 0 | ZF2: 0 | ZG2: 0 | ZH2: 0 | ZI2: 0 | ZJ2: 0 | ZK2: 0 | ZL2: 0 | ZM2: 0 | ZN2: 0 | ZO2: 0 | ZP2: 0 | ZQ2: 0 | ZR2: 0 | ZS2: 0 | ZT2: 0 | ZU2: 0 | ZV2: 0 | ZW2: 0 | ZX2: 0 | ZY2: 0 | ZZ2: 0 | AAA2: 0 | AAB2: 0 | AAC2: 0 | AAD2: 0 | AAE2: 0 | AAF2: 0 | AAG2: 0 | AAH2: 0 | AAI2: 0 | AAJ2: 0 | AAK2: 0 | AAL2: 0 | AAM2: 0 | AAN2: 0 | AAO2: 0 | AAP2: 0 | AAQ2: 0 | AAR2: 0 | AAS2: 0 | AAT2: 0 | AAU2: 0 | AAV2: 0 | AAW2: 0 | AAX2: 0 | AAY2: 0 | AAZ2: 0 | ABA2: 0 | ABB2: 0 | ABC2: 0 | ABD2: 0 | ABE2: 0 | ABF2: 0 | ABG2: 0 | ABH2: 0 | ABI2: 0 | ABJ2: 0 | ABK2: 0 | ABL2: 0 | ABM2: 0 | ABN2: 0 | ABO2: 0 | ABP2: 0 | ABQ2: 0 | ABR2: 0 | ABS2: 0 | ABT2: 0 | ABU2: 0 | ABV2: 0 | ABW2: 0 | ABX2: 0 | ABY2: 0 | ABZ2: 0 | ACA2: 0 | ACB2: 0 | ACC2: 0 | ACD2: 0 | ACE2: 0 | ACF2: 0 | ACG2: 0 | ACH2: 0 | ACI2: 0 | ACJ2: 0 | ACK2: 0 | ACL2: 0 | ACM2: 0 | ACN2: 0 | ACO2: 0 | ACP2: 0 | ACQ2: 0 | ACR2: 0 | ACS2: 0 | ACT2: 0 | ACU2: 0 | ACV2: 0 | ACW2: 0 | ACX2: 0 | ACY2: 0 | ACZ2: 0 | ADA2: 0 | ADB2: 0 | ADC2: 0 | ADD2: 0 | ADE2: 0 | ADF2: 0 | ADG2: 0 | ADH2: 0 | ADI2: 0 | ADJ2: 0 | ADK2: 0 | ADL2: 0 | ADM2: 0 | ADN2: 0 | ADO2: 0 | ADP2: 0 | ADQ2: 0 | ADR2: 0 | ADS2: 0 | ADT2: 0 | ADU2: 0 | ADV2: 0 | ADW2: 0 | ADX2: 0 | ADY2: 0 | ADZ2: 0 | AEA2: 0 | AEB2: 0 | AEC2: 0 | AED2: 0 | AEE2: 0 | AEF2: 0 | AEG2: 0 | AEH2: 0 | AEI2: 0 | AEJ2: 0 | AEK2: 0 | AEL2: 0 | AEM2: 0 | AEN2: 0 | AEO2: 0 | AEP2: 0 | AEQ2: 0 | AER2: 0 | AES2: 0 | AET2: 0 | AEU2: 0 | AEV2: 0 | AEW2: 0 | AEX2: 0 | AEY2: 0 | AEZ2: 0 | AFA2: 0 | AFB2: 0 | AFC2: 0 | AFD2: 0 | AFE2: 0 | AFF2: 0 | AFG2: 0 | AFH2: 0 | AFI2: 0 | AFJ2: 0 | AFK2: 0 | AFL2: 0 | AFM2: 0 | AFN2: 0 | AFO2: 0 | AFP2: 0 | AFQ2: 0 | AFR2: 0 | AFS2: 0 | AFT2: 0 | AFU2: 0 | AFV2: 0 | AFW2: 0 | AFX2: 0 | AFY2: 0 | AFZ2: 0 | AGA2: 0 | AGB2: 0 | AGC2: 0 | AGD2: 0 | AGE2: 0 | AGF2: 0 | AGG2: 0 | AGH2: 0 | AGI2: 0 | AGJ2: 0 | AGK2: 0 | AGL2: 0 | AGM2: 0 | AGN2: 0 | AGO2: 0 | AGP2: 0 | AGQ2: 0 | AGR2: 0 | AGS2: 0 | AGT2: 0 | AGU2: 0 | AGV2: 0 | AGW2: 0 | AGX2: 0 | AGY2: 0 | AGZ2: 0 | AHA2: 0 | AHB2: 0 | AHC2: 0 | AHD2: 0 | AHE2: 0 | AHF2: 0 | AHG2: 0 | AHH2: 0 | AHI2: 0 | AHJ2: 0 | AHK2: 0 | AHL2: 0 | AHM2: 0 | AHN2: 0 | AHO2: 0 | AHP2: 0 | AHQ2: 0 | AHR2: 0 | AHS2: 0 | AHT2: 0 | AHU2: 0 | AHV2: 0 | AHW2: 0 | AHX2: 0 | AHY2: 0 | AHZ2: 0 | AIA2: 0 | AIB2: 0 | AIC2: 0 | AID2: 0 | AIE2: 0 | AIF2: 0 | AIG2: 0 | AIH2: 0 | AII2: 0 | AIJ2: 0 | AIK2: 0 | AIL2: 0 | AIM2: 0 | AIN2: 0 | AIO2: 0 | AIP2: 0 | AIQ2: 0 | AIR2: 0 | AIS2: 0 | AIT2: 0 | AIU2: 0 | AIV2: 0 | AIW2: 0 | AIX2: 0 | AIY2: 0 | AIZ2: 0 | AJA2: 0 | AJB2: 0 | AJC2: 0 | AJD2: 0 | AJE2: 0 | AJF2: 0 | AJG2: 0 | AJH2: 0 | AJI2: 0 | AJJ2: 0 | AJK2: 0 | AJL2: 0 | AJM2: 0 | AJN2: 0 | AJO2: 0 | AJP2: 0 | AJQ2: 0 | AJR2: 0 | AJS2: 0 | AJT2: 0 | AJU2: 0 | AJV2: 0 | AJW2: 0 | AJX2: 0 | AJY2: 0 | AJZ2: 0 | AKA2: 0 | AKB2: 0 | AKC2: 0 | AKD2: 0 | AKE2: 0 | AKF2: 0 | AKG2: 0 | AKH2: 0 | AKI2: 0 | AKJ2: 0 | AKK2: 0 | AKL2: 0 | AKM2: 0 | AKN2: 0 | AKO2: 0 | AKP2: 0 | AKQ2: 0 | AKR2: 0 | AKS2: 0 | AKT2: 0 | AKU2: 0 | AKV2: 0 | AKW2: 0 | AKX2: 0 | AKY2: 0 | AKZ2: 0 | ALA2: 0 | ALB2: 0 | ALC2: 0 | ALD2: 0 | ALE2: 0 | ALF2: 0 | ALG2: 0 | ALH2: 0 | ALI2: 0 | ALJ2: 0 | ALK2: 0 | ALL2: 0 | ALM2: 0 | ALN2: 0 | ALO2: 0 | ALP2: 0 | ALQ2: 0 | ALR2: 0 | ALS2: 0 | ALT2: 0 | ALU2: 0 | ALV2: 0 | ALW2: 0 | ALX2: 0 | ALY2: 0 | ALZ2: 0 | AMA2: 0 | AMB2: 0 | AMC2: 0 | AMD2: 0 | AME2: 0 | AMF2: 0 | AMG2: 0 | AMH2: 0 | AMI2: 0 | AMJ2: 0 | AMK2: 0 | AML2: 0 | AMM2: 0 | AMN2: 0 | AMO2: 0 | AMP2: 0 | AMQ2: 0 | AMR2: 0 | AMS2: 0 | AMT2: 0 | AMU2: 0 | AMV2: 0 | AMW2: 0 | AMX2: 0 | AMY2: 0 | AMZ2: 0 | ANA2: 0 | ANB2: 0 | ANC2: 0 | AND2: 0 | ANE2: 0 | ANF2: 0 | ANG2: 0 | ANH2: 0 | ANI2: 0 | ANJ2: 0 | ANK2: 0 | ANL2: 0 | ANM2: 0 | ANN2: 0 | ANO2: 0 | ANP2: 0 | ANQ2: 0 | ANR2: 0 | ANS2: 0 | ANT2: 0 | ANU2: 0 | ANV2: 0 | ANW2: 0 | ANX2: 0 | ANY2: 0 | ANZ2: 0 | AOA2: 0 | AOB2: 0 | AOC2: 0 | AOD2: 0 | AOE2: 0 | AOF2: 0 | AOG2: 0 | AOH2: 0 | AOI2: 0 | AOJ2: 0 | AOK2: 0 | AOL2: 0 | AOM2: 0 | AON2: 0 | AOO2: 0 | AOP2: 0 | AOQ2: 0 | AOR2: 0 | AOS2: 0 | AOT2: 0 | AOU2: 0 | AOV2: 0 | AOW2: 0 | AOX2: 0 | AOY2: 0 | AOZ2: 0 | APA2: 0 | APB2: 0 | APC2: 0 | APD2: 0 | APE2: 0 | APF2: 0 | APG2: 0 | APH2: 0 | API2: 0 | APJ2: 0 | APK2: 0 | APL2: 0 | APM2: 0 | APN2: 0 | APO2: 0 | APP2: 0 | APQ2: 0 | APR2: 0 | APS2: 0 | APT2: 0 | APU2: 0 | APV2: 0 | APW2: 0 | APX2: 0 | APY2: 0 | APZ2: 0 | AQA2: 0 | AQB2: 0 | AQC2: 0 | AQD2: 0 | AQE2: 0 | AQF2: 0 | AQG2: 0 | AQH2: 0 | AQI2: 0 | AQJ2: 0 | AQK2: 0 | AQL2: 0 | AQM2: 0 | AQN2: 0 | AQO2: 0 | AQP2: 0 | AQQ2: 0 | AQR2: 0 | AQS2: 0 | AQT2: 0 | AQU2: 0 | AQV2: 0 | AQW2: 0 | AQX2: 0 | AQY2: 0 | AQZ2: 0 | ARA2: 0 | ARB2: 0 | ARC2: 0 | ARD2: 0 | ARE2: 0 | ARF2: 0 | ARG2: 0 | ARH2: 0 | ARI2: 0 | ARJ2: 0 | ARK2: 0 | ARL2: 0 | ARM2: 0 | ARN2: 0 | ARO2: 0 | ARP2: 0 | ARQ2: 0 | ARR2: 0 | ARS2: 0 | ART2: 0 | ARU2: 0 | ARV2: 0 | ARW2: 0 | ARX2: 0 | ARY2: 0 | ARZ2: 0 | ASA2: 0 | ASB2: 0 | ASC2: 0 | ASD2: 0 | ASE2: 0 | ASF2: 0 | ASG2: 0 | ASH2: 0 | ASI2: 0 | ASJ2: 0 | ASK2: 0 | ASL2: 0 | ASM2: 0 | ASN2: 0 | ASO2: 0 | ASP2: 0 | ASQ2: 0 | ASR2: 0 | ASS2: 0 | AST2: 0 | ASU2: 0 | ASV2: 0 | ASW2: 0 | ASX2: 0 | ASY2: 0 | ASZ2: 0 | ATA2: 0 | ATB2: 0 | ATC2: 0 | ATD2: 0 | ATE2: 0 | ATF2: 0 | ATG2: 0 | ATH2: 0 | ATI2: 0 | ATJ2: 0 | ATK2: 0 | ATL2: 0 | ATM2: 0 | ATN2: 0 | ATO2: 0 | ATP2: 0 | ATQ2: 0 | ATR2: 0 | ATS2: 0 | ATT2: 0 | ATU2: 0 | ATV2: 0 | ATW2: 0 | ATX2: 0 | ATY2: 0 | ATZ2: 0 | AUA2: 0 | AUB2: 0 | AUC2: 0 | AUD2: 0 | AUE2: 0 | AUF2: 0 | AUG2: 0 | AUH2: 0 | AUI2: 0 | AUJ2: 0 | AUK2: 0 | AUL2: 0 | AUM2: 0 | AUN2: 0 | AUO2: 0 | AUP2: 0 | AUQ2: 0 | AUR2: 0 | AUS2: 0 | AUT2: 0 | AUU2: 0 | AUV2: 0 | AUW2: 0 | AUX2: 0 | AUY2: 0 | AUZ2: 0 | AVA2: 0 | AVB2: 0 | AVC2: 0 | AVD2: 0 | AVE2: 0 | AVF2: 0 | AVG2: 0 | AVH2: 0 | AVI2: 0 | AVJ2: 0 | AVK2: 0 | AVL2: 0 | AVM2: 0 | AVN2: 0 | AVO2: 0 | AVP2: 0 | AVQ2: 0 | AVR2: 0 | AVS2: 0 | AVT2: 0 | AVU2: 0 | AVV2: 0 | AVW2: 0 | AVX2: 0 | AVY2: 0 | AVZ2: 0 | AWA2: 0 | AWB2: 0 | AWC2: 0 | AWD2: 0 | AWE2: 0 | AWF2: 0 | AWG2: 0 | AWH2: 0 | AWI2: 0 | AWJ2: 0 | AWK2: 0 | AWL2: 0 | AWM2: 0 | AWN2: 0 | AWO2: 0 | AWP2: 0 | AWQ2: 0 | AWR2: 0 | AWS2: 0 | AWT2: 0 | AWU2: 0 | AWV2: 0 | AWW2: 0 | AWX2: 0 | AWY2: 0 | AWZ2: 0 | AXA2: 0 | AXB2: 0 | AXC2: 0 | AXD2: 0 | AXE2: 0 | AXF2: 0 | AXG2: 0 | AXH2: 0 | AXI2: 0 | AXJ2: 0 | AXK2: 0 | AXL2: 0 | AXM2: 0 | AXN2: 0 | AXO2: 0 | AXP2: 0 | AXQ2: 0 | AXR2: 0 | AXS2: 0 | AXT2: 0 | AXU2: 0 | AXV2: 0 | AXW2: 0 | AXX2: 0 | AXY2: 0 | AXZ2: 0 | AYA2: 0 | AYB2: 0 | AYC2: 0 | AYD2: 0 | AYE2: 0 | AYF2: 0 | AYG2: 0 | AYH2: 0 | AYI2: 0 | AYJ2: 0 | AYK2: 0 | AYL2: 0 | AYM2: 0 | AYN2: 0 | AYO2: 0 | AYP2: 0 | AYQ2: 0 | AYR2: 0 | AYS2: 0 | AYT2: 0 | AYU2: 0 | AYV2: 0 | AYW2: 0 | AYX2: 0 | AYY2: 0 | AYZ2: 0 | AZA2: 0 | AZB2: 0 | AZC2: 0 | AZD2: 0 | AZE2: 0 | AZF2: 0 | AZG2: 0 | AZH2: 0 | AZI2: 0 | AZJ2: 0 | AZK2: 0 | AZL2: 0 | AZM2: 0 | AZN2: 0 | AZO2: 0 | AZP2: 0 | AZQ2: 0 | AZR2: 0 | AZS2: 0 | AZT2: 0 | AZU2: 0 | AZV2: 0 | AZW2: 0 | AZX2: 0 | AZY2: 0 | AZZ2: 0 | BAA2: 0
